[2024-05-18T16:20:27.763+0000] {taskinstance.py:1956} INFO - Dependencies all met for dep_context=non-requeueable deps ti=<TaskInstance: our_first_dag_v2.seceond_task manual__2024-05-18T16:16:48.262081+00:00 [queued]>
[2024-05-18T16:20:27.772+0000] {taskinstance.py:1956} INFO - Dependencies all met for dep_context=requeueable deps ti=<TaskInstance: our_first_dag_v2.seceond_task manual__2024-05-18T16:16:48.262081+00:00 [queued]>
[2024-05-18T16:20:27.772+0000] {taskinstance.py:2170} INFO - Starting attempt 1 of 1
[2024-05-18T16:20:27.788+0000] {taskinstance.py:2191} INFO - Executing <Task(BashOperator): seceond_task> on 2024-05-18 16:16:48.262081+00:00
[2024-05-18T16:20:27.797+0000] {standard_task_runner.py:60} INFO - Started process 3282 to run task
[2024-05-18T16:20:27.800+0000] {standard_task_runner.py:87} INFO - Running: ['***', 'tasks', 'run', 'our_first_dag_v2', 'seceond_task', 'manual__2024-05-18T16:16:48.262081+00:00', '--job-id', '376', '--raw', '--subdir', 'DAGS_FOLDER/frist-dag.py', '--cfg-path', '/tmp/tmp9wlhgnmf']
[2024-05-18T16:20:27.802+0000] {standard_task_runner.py:88} INFO - Job 376: Subtask seceond_task
[2024-05-18T16:20:27.854+0000] {task_command.py:423} INFO - Running <TaskInstance: our_first_dag_v2.seceond_task manual__2024-05-18T16:16:48.262081+00:00 [running]> on host 7b23a6949395
[2024-05-18T16:20:27.947+0000] {taskinstance.py:2480} INFO - Exporting env vars: AIRFLOW_CTX_DAG_OWNER='***' AIRFLOW_CTX_DAG_ID='our_first_dag_v2' AIRFLOW_CTX_TASK_ID='seceond_task' AIRFLOW_CTX_EXECUTION_DATE='2024-05-18T16:16:48.262081+00:00' AIRFLOW_CTX_TRY_NUMBER='1' AIRFLOW_CTX_DAG_RUN_ID='manual__2024-05-18T16:16:48.262081+00:00'
[2024-05-18T16:20:27.954+0000] {subprocess.py:63} INFO - Tmp dir root location: /tmp
[2024-05-18T16:20:27.955+0000] {subprocess.py:75} INFO - Running command: ['/usr/bin/bash', '-c', 'wc -l output.csv']
[2024-05-18T16:20:27.972+0000] {subprocess.py:86} INFO - Output:
[2024-05-18T16:20:27.976+0000] {subprocess.py:93} INFO - wc: output.csv: No such file or directory
[2024-05-18T16:20:27.977+0000] {subprocess.py:97} INFO - Command exited with return code 1
[2024-05-18T16:20:27.989+0000] {taskinstance.py:2698} ERROR - Task failed with exception
Traceback (most recent call last):
  File "/home/airflow/.local/lib/python3.8/site-packages/airflow/models/taskinstance.py", line 433, in _execute_task
    result = execute_callable(context=context, **execute_callable_kwargs)
  File "/home/airflow/.local/lib/python3.8/site-packages/airflow/operators/bash.py", line 212, in execute
    raise AirflowException(
airflow.exceptions.AirflowException: Bash command failed. The command returned a non-zero exit code 1.
[2024-05-18T16:20:27.993+0000] {taskinstance.py:1138} INFO - Marking task as FAILED. dag_id=our_first_dag_v2, task_id=seceond_task, execution_date=20240518T161648, start_date=20240518T162027, end_date=20240518T162027
[2024-05-18T16:20:28.008+0000] {standard_task_runner.py:107} ERROR - Failed to execute job 376 for task seceond_task (Bash command failed. The command returned a non-zero exit code 1.; 3282)
[2024-05-18T16:20:28.053+0000] {local_task_job_runner.py:234} INFO - Task exited with return code 1
[2024-05-18T16:20:28.074+0000] {taskinstance.py:3280} INFO - 0 downstream tasks scheduled from follow-on schedule check
