[2024-05-18T16:16:50.709+0000] {taskinstance.py:1956} INFO - Dependencies all met for dep_context=non-requeueable deps ti=<TaskInstance: our_first_dag_v2.wget manual__2024-05-18T16:16:48.262081+00:00 [queued]>
[2024-05-18T16:16:50.718+0000] {taskinstance.py:1956} INFO - Dependencies all met for dep_context=requeueable deps ti=<TaskInstance: our_first_dag_v2.wget manual__2024-05-18T16:16:48.262081+00:00 [queued]>
[2024-05-18T16:16:50.719+0000] {taskinstance.py:2170} INFO - Starting attempt 1 of 11
[2024-05-18T16:16:50.733+0000] {taskinstance.py:2191} INFO - Executing <Task(BashOperator): wget> on 2024-05-18 16:16:48.262081+00:00
[2024-05-18T16:16:50.741+0000] {standard_task_runner.py:60} INFO - Started process 3206 to run task
[2024-05-18T16:16:50.744+0000] {standard_task_runner.py:87} INFO - Running: ['***', 'tasks', 'run', 'our_first_dag_v2', 'wget', 'manual__2024-05-18T16:16:48.262081+00:00', '--job-id', '372', '--raw', '--subdir', 'DAGS_FOLDER/frist-dag.py', '--cfg-path', '/tmp/tmp69klibz4']
[2024-05-18T16:16:50.746+0000] {standard_task_runner.py:88} INFO - Job 372: Subtask wget
[2024-05-18T16:16:50.795+0000] {task_command.py:423} INFO - Running <TaskInstance: our_first_dag_v2.wget manual__2024-05-18T16:16:48.262081+00:00 [running]> on host 7b23a6949395
[2024-05-18T16:16:50.890+0000] {taskinstance.py:2480} INFO - Exporting env vars: AIRFLOW_CTX_DAG_OWNER='omar' AIRFLOW_CTX_DAG_ID='our_first_dag_v2' AIRFLOW_CTX_TASK_ID='wget' AIRFLOW_CTX_EXECUTION_DATE='2024-05-18T16:16:48.262081+00:00' AIRFLOW_CTX_TRY_NUMBER='1' AIRFLOW_CTX_DAG_RUN_ID='manual__2024-05-18T16:16:48.262081+00:00'
[2024-05-18T16:16:50.894+0000] {subprocess.py:63} INFO - Tmp dir root location: /tmp
[2024-05-18T16:16:50.896+0000] {subprocess.py:75} INFO - Running command: ['/usr/bin/bash', '-c', 'curl -sS https://data.cityofnewyork.us/api/views/kxp8-n2sj/rows.csv?accessType=DOWNLOAD > /opt/***/output.csv']
[2024-05-18T16:16:50.913+0000] {subprocess.py:86} INFO - Output:
[2024-05-18T16:17:41.302+0000] {local_task_job_runner.py:302} WARNING - State of this instance has been externally set to failed. Terminating instance.
[2024-05-18T16:17:41.307+0000] {process_utils.py:131} INFO - Sending 15 to group 3206. PIDs of all processes in the group: [3207, 3208, 3206]
[2024-05-18T16:17:41.308+0000] {process_utils.py:86} INFO - Sending the signal 15 to group 3206
[2024-05-18T16:17:41.308+0000] {taskinstance.py:2450} ERROR - Received SIGTERM. Terminating subprocesses.
[2024-05-18T16:17:41.309+0000] {subprocess.py:104} INFO - Sending SIGTERM signal to process group
[2024-05-18T16:17:41.361+0000] {process_utils.py:79} INFO - Process psutil.Process(pid=3206, status='terminated', exitcode=0, started='16:16:50') (3206) terminated with exit code 0
[2024-05-18T16:17:41.362+0000] {process_utils.py:79} INFO - Process psutil.Process(pid=3207, status='terminated', started='16:16:50') (3207) terminated with exit code None
[2024-05-18T16:17:41.363+0000] {process_utils.py:79} INFO - Process psutil.Process(pid=3208, status='terminated', started='16:16:50') (3208) terminated with exit code None
